<?xml version="1.0"?>
<robot name="humanoid">
  <link name="Torso_link">
    <inertial>
        <mass value="1" />
        <inertia ixx="0.0375" ixy="0.0" ixz="0.0" iyy="0.031875" iyz="0.0" izz="0.009375"/>
    </inertial>
    <collision>
    <origin rpy="0.0 0.0 0.0" xyz="0.0 0.0 1.1" />
      <geometry>
        <box size="0.15 0.3 0.6" />
      </geometry>
        </collision>
    <visual>
    <origin rpy="0.0 0.0 0.0" xyz="0.0 0.0 1.1" />
      <geometry>
        <box size="0.15 0.3 0.6" />
      </geometry>
    </visual>
  </link>

  <link name="Head_link">
    <inertial>
        <mass value="1" />
        <inertia ixx="0.0375" ixy="0.0" ixz="0.0" iyy="0.031875" iyz="0.0" izz="0.009375"/>
    </inertial>
    <collision>
    <origin rpy="0.0 0.0 0.0" xyz="0.0 0.0 0.1" />
      <geometry>
        <box size="0.15 0.15 0.2" />
      </geometry>
        </collision>
    <visual>
    <origin rpy="0.0 0.0 0.0" xyz="0.0 0.0 0.1" />
      <geometry>
        <box size="0.15 0.15 0.2" />
      </geometry>
    </visual>
  </link>


  <link name="Leftleg_link">
    <inertial>
        <mass value="10" />
        <inertia ixx="0.53958" ixy="0.0" ixz="0.0" iyy="0.53958" iyz="0.0" izz="0.0125"/>
    </inertial>
    <collision>
    <origin rpy="0.0 0.0 0.0" xyz="0.0 0.0 -0.4" />
      <geometry>
        <cylinder radius="0.05" length="0.8" />
      </geometry>
    </collision>
    <visual>
    <origin rpy="0.0 0.0 0.0" xyz="0.0 0.0 -0.4" />
      <geometry>
        <cylinder radius="0.05" length="0.8" />
      </geometry>
    </visual>
  </link>

  <link name="Rightleg_link">
    <inertial>
        <mass value="10" />
        <inertia ixx="0.53958" ixy="0.0" ixz="0.0" iyy="0.53958" iyz="0.0" izz="0.0125"/>
    </inertial>
    <collision>
    <origin rpy="0.0 0.0 0.0" xyz="0.0 -0.0 -0.4" />
      <geometry>
        <cylinder radius="0.05" length="0.8" />
      </geometry>
    </collision>
    <visual>
    <origin rpy="0.0 0.0 0.0" xyz="0.0 -0.0 -0.4" />
      <geometry>
        <cylinder radius="0.05" length="0.8" />
      </geometry>
    </visual>
  </link>

  <link name="LeftUpperArm_link">
    <inertial>
        <mass value="1" />
        <inertia ixx="0.053958" ixy="0.0" ixz="0.0" iyy="0.053958" iyz="0.0" izz="0.00125"/>
    </inertial>
    <collision>
    <origin rpy="1.5708 0.0 0.0" xyz="0.0 0.15 0.0" />
      <geometry>
        <cylinder radius="0.03" length="0.3" />
      </geometry>
    </collision>
    <visual>
    <origin rpy="1.5708 0.0 0.0" xyz="0.0 0.15 0.0" />
      <geometry>
        <cylinder radius="0.03" length="0.3" />
      </geometry>
    </visual>
  </link>

  <link name="LeftForeArm_link">
    <inertial>
        <mass value="1" />
        <inertia ixx="0.053958" ixy="0.0" ixz="0.0" iyy="0.053958" iyz="0.0" izz="0.00125"/>
    </inertial>
    <collision>
    <origin rpy="1.5708 0.0 0.0" xyz="0.0 0.15 0.0" />
      <geometry>
        <cylinder radius="0.03" length="0.3" />
      </geometry>
    </collision>
    <visual>
    <origin rpy="1.5708 0.0 0.0" xyz="0.0 0.15 0.0" />
      <geometry>
        <cylinder radius="0.03" length="0.3" />
      </geometry>
    </visual>
  </link>

  <link name="RightUpperArm_link">
    <inertial>
        <mass value="1" />
        <inertia ixx="0.053958" ixy="0.0" ixz="0.0" iyy="0.053958" iyz="0.0" izz="0.00125"/>
    </inertial>
    <collision>
    <origin rpy="1.5708 0.0 0.0" xyz="0.0 -0.15 0.0" />
      <geometry>
        <cylinder radius="0.03" length="0.3" />
      </geometry>
    </collision>
    <visual>
    <origin rpy="1.5708 0.0 0.0" xyz="0.0 -0.15 0.0" />
      <geometry>
        <cylinder radius="0.03" length="0.3" />
      </geometry>
    </visual>
  </link>

  <link name="RightForeArm_link">
    <inertial>
        <mass value="1" />
        <inertia ixx="0.053958" ixy="0.0" ixz="0.0" iyy="0.053958" iyz="0.0" izz="0.00125"/>
    </inertial>
    <collision>
    <origin rpy="1.5708 0.0 0.0" xyz="0.0 -0.15 0.0" />
      <geometry>
        <cylinder radius="0.03" length="0.3" />
      </geometry>
    </collision>
    <visual>
    <origin rpy="1.5708 0.0 0.0" xyz="0.0 -0.15 0.0" />
      <geometry>
        <cylinder radius="0.03" length="0.3" />
      </geometry>
    </visual>
  </link>

  <!-- <joint name="base_to_second_joint" type="continuous">
    <parent link="base_link"/>
    <child link="second_link"/>
    <axis xyz="1 0 0"/>
    <origin xyz="0.0 0.0 0.2" rpy="0.0 0.0 0.0"/> 
  </joint> -->



  <joint name="Leftleg_joint" type="revolute">
  <origin xyz="0.0 0.1 0.8" rpy="0.0 0.0 0.0"/> 
    <parent link="Torso_link"/>
    <child link="Leftleg_link"/>
    <axis xyz="1 0 0"/>
    <limit effort="30" velocity="1.0" lower="-0.5" upper="0.5" />
  </joint>

  <joint name="Rightleg_joint" type="revolute">
  <origin xyz="0.0 -0.1 0.8" rpy="0.0 0.0 0.0"/> 
    <parent link="Torso_link"/>
    <child link="Rightleg_link"/>
    <axis xyz="1 0 0"/>
    <limit effort="30" velocity="1.0" lower="-0.5" upper="0.5" />
  </joint>

  <joint name="LeftUpperArm_joint" type="revolute">
  <origin xyz="0.0 0.15 1.3" rpy="0.0 0.0 0.0"/> 
    <parent link="Torso_link"/>
    <child link="LeftUpperArm_link"/>
    <axis xyz="1 0 0"/>
    <limit effort="30" velocity="1.0" lower="-0.0" upper="0.0" />
  </joint>

  <joint name="LeftForeArm_joint" type="revolute">
  <origin xyz="0.0 0.3 0.0" rpy="0.0 0.0 0.0"/> 
    <parent link="LeftUpperArm_link"/>
    <child link="LeftForeArm_link"/>
    <axis xyz="1 0 0"/>
    <limit effort="30" velocity="1.0" lower="-0.7854" upper="0.7854" />
  </joint>

  <joint name="RightUpperArm_joint" type="revolute" >
  <origin xyz="0.0 -0.15 1.3" rpy="0.0 0.0 0.0"/> 
    <parent link="Torso_link"/>
    <child link="RightUpperArm_link"/>
    <axis xyz="1 0 0"/>
    <limit effort="30" velocity="1.0" lower="-0.0" upper="0.0" />
  </joint>

  <joint name="RightForeArm_joint" type="revolute" >
  <origin xyz="0.0 -0.3 0.0" rpy="0.0 0.0 0.0"/> 
    <parent link="RightUpperArm_link"/>
    <child link="RightForeArm_link"/>
    <axis xyz="1 0 0"/>
    <limit effort="30" velocity="1.0" lower="-0.7854" upper="0.7854" />
  </joint>

  <joint name="Head_joint" type="fixed">
  <origin xyz="0.0 0.0 1.4" rpy="0.0 0.0 0.0"/> 
    <parent link="Torso_link"/>
    <child link="Head_link"/>
    <axis xyz="0 0 1"/>
  </joint>

</robot>